<?xml version="1.0" encoding="UTF-8"?>
<!-- Generated by org.testng.reporters.JUnitReportReporter -->
<testsuite hostname="TVMATP310440M" name="com.uom.tests.ManageLocation" tests="3" failures="1" timestamp="10 Nov 2016 12:03:07 GMT" time="583.428" errors="2">
  <testcase name="INV_ML_014_TI_057_DefaultLoc_DeleteAllLocation_SetupCustomLocations_VerifyTrackInventory" time="574.997" classname="com.uom.tests.ManageLocation">
    <error type="java.lang.AssertionError" message="expected [true] but found [false]">
      <![CDATA[java.lang.AssertionError: expected [true] but found [false]
	at org.testng.Assert.fail(Assert.java:94)
	at org.testng.Assert.failNotEquals(Assert.java:494)
	at org.testng.Assert.assertTrue(Assert.java:42)
	at org.testng.Assert.assertTrue(Assert.java:52)
	at com.framework.reporting.FrameworkReporter.fail(FrameworkReporter.java:32)
	at com.uom.pages.common.LocationsPage.verifyAssignedProductsInInventoryList(LocationsPage.java:2897)
	at com.uom.tests.ManageLocation.INV_ML_014_TI_057_DefaultLoc_DeleteAllLocation_SetupCustomLocations_VerifyTrackInventory(ManageLocation.java:852)
	at sun.reflect.NativeMethodAccessorImpl.invoke0(Native Method)
	at sun.reflect.NativeMethodAccessorImpl.invoke(NativeMethodAccessorImpl.java:62)
	at sun.reflect.DelegatingMethodAccessorImpl.invoke(DelegatingMethodAccessorImpl.java:43)
	at java.lang.reflect.Method.invoke(Method.java:497)
	at org.testng.internal.MethodInvocationHelper.invokeMethod(MethodInvocationHelper.java:84)
	at org.testng.internal.Invoker.invokeMethod(Invoker.java:714)
	at org.testng.internal.Invoker.retryFailed(Invoker.java:1049)
	at org.testng.internal.TestMethodWithDataProviderMethodWorker.call(TestMethodWithDataProviderMethodWorker.java:96)
	at org.testng.internal.TestMethodWithDataProviderMethodWorker.call(TestMethodWithDataProviderMethodWorker.java:14)
	at java.util.concurrent.FutureTask.run(FutureTask.java:266)
	at java.util.concurrent.Executors$RunnableAdapter.call(Executors.java:511)
	at java.util.concurrent.FutureTask.run(FutureTask.java:266)
	at java.util.concurrent.ThreadPoolExecutor.runWorker(ThreadPoolExecutor.java:1142)
	at java.util.concurrent.ThreadPoolExecutor$Worker.run(ThreadPoolExecutor.java:617)
	at java.lang.Thread.run(Thread.java:745)
]]>
    </error>
  </testcase> <!-- INV_ML_014_TI_057_DefaultLoc_DeleteAllLocation_SetupCustomLocations_VerifyTrackInventory -->
  <testcase name="INV_ML_015_TI_058_DefaultLoc_DeleteAllLoc_SuggestedCat_SetupCustomLo_VerifyTrackInventory" time="4.682" classname="com.uom.tests.ManageLocation">
    <error type="java.lang.AssertionError" message="expected [true] but found [false]">
      <![CDATA[java.lang.AssertionError: expected [true] but found [false]
	at org.testng.Assert.fail(Assert.java:94)
	at org.testng.Assert.failNotEquals(Assert.java:494)
	at org.testng.Assert.assertTrue(Assert.java:42)
	at org.testng.Assert.assertTrue(Assert.java:52)
	at com.framework.reporting.FrameworkReporter.fail(FrameworkReporter.java:32)
	at com.framework.frameworkFunctions.LibraryPage.isElementPresentAfterWait(LibraryPage.java:416)
	at com.uom.pages.common.HomePage.logoutAfterCheck(HomePage.java:271)
	at com.uom.components.Components.login(Components.java:85)
	at com.uom.tests.ManageLocation.INV_ML_015_TI_058_DefaultLoc_DeleteAllLoc_SuggestedCat_SetupCustomLo_VerifyTrackInventory(ManageLocation.java:907)
	at sun.reflect.NativeMethodAccessorImpl.invoke0(Native Method)
	at sun.reflect.NativeMethodAccessorImpl.invoke(NativeMethodAccessorImpl.java:62)
	at sun.reflect.DelegatingMethodAccessorImpl.invoke(DelegatingMethodAccessorImpl.java:43)
	at java.lang.reflect.Method.invoke(Method.java:497)
	at org.testng.internal.MethodInvocationHelper.invokeMethod(MethodInvocationHelper.java:84)
	at org.testng.internal.Invoker.invokeMethod(Invoker.java:714)
	at org.testng.internal.Invoker.invokeTestMethod(Invoker.java:901)
	at org.testng.internal.TestMethodWithDataProviderMethodWorker.call(TestMethodWithDataProviderMethodWorker.java:73)
	at org.testng.internal.TestMethodWithDataProviderMethodWorker.call(TestMethodWithDataProviderMethodWorker.java:14)
	at java.util.concurrent.FutureTask.run(FutureTask.java:266)
	at java.util.concurrent.Executors$RunnableAdapter.call(Executors.java:511)
	at java.util.concurrent.FutureTask.run(FutureTask.java:266)
	at java.util.concurrent.ThreadPoolExecutor.runWorker(ThreadPoolExecutor.java:1142)
	at java.util.concurrent.ThreadPoolExecutor$Worker.run(ThreadPoolExecutor.java:617)
	at java.lang.Thread.run(Thread.java:745)
]]>
    </error>
  </testcase> <!-- INV_ML_015_TI_058_DefaultLoc_DeleteAllLoc_SuggestedCat_SetupCustomLo_VerifyTrackInventory -->
  <testcase name="INV_ML_016_TI_059_CustomLoc_DeleteAllLoc_CustomCat_SetupCustomLoc_VerifyTrackInventory" time="3.749" classname="com.uom.tests.ManageLocation">
    <failure type="org.openqa.selenium.remote.UnreachableBrowserException" message="Error communicating with the remote browser. It may have died.
Build info: version: &#039;2.48.2&#039;, revision: &#039;41bccdd&#039;, time: &#039;2015-10-09 19:59:12&#039;
System info: host: &#039;TVMATP310440M&#039;, ip: &#039;10.155.190.178&#039;, os.name: &#039;Mac OS X&#039;, os.arch: &#039;x86_64&#039;, os.version: &#039;10.12&#039;, java.version: &#039;1.8.0_40&#039;
Driver info: driver.version: AppiumDriver">
      <![CDATA[org.openqa.selenium.remote.UnreachableBrowserException: Error communicating with the remote browser. It may have died.
Build info: version: '2.48.2', revision: '41bccdd', time: '2015-10-09 19:59:12'
System info: host: 'TVMATP310440M', ip: '10.155.190.178', os.name: 'Mac OS X', os.arch: 'x86_64', os.version: '10.12', java.version: '1.8.0_40'
Driver info: driver.version: AppiumDriver
	at org.openqa.selenium.remote.RemoteWebDriver.execute(RemoteWebDriver.java:641)
	at io.appium.java_client.DefaultGenericMobileDriver.execute(DefaultGenericMobileDriver.java:51)
	at io.appium.java_client.AppiumDriver.execute(AppiumDriver.java:268)
	at io.appium.java_client.AppiumDriver.getContextHandles(AppiumDriver.java:595)
	at com.framework.frameworkFunctions.LibraryPage.switchToWebContext(LibraryPage.java:575)
	at com.uom.pages.common.HomePage.logoutAfterCheck(HomePage.java:270)
	at com.uom.components.Components.login(Components.java:85)
	at com.uom.tests.ManageLocation.INV_ML_016_TI_059_CustomLoc_DeleteAllLoc_CustomCat_SetupCustomLoc_VerifyTrackInventory(ManageLocation.java:1011)
	at sun.reflect.NativeMethodAccessorImpl.invoke0(Native Method)
	at sun.reflect.NativeMethodAccessorImpl.invoke(NativeMethodAccessorImpl.java:62)
	at sun.reflect.DelegatingMethodAccessorImpl.invoke(DelegatingMethodAccessorImpl.java:43)
	at java.lang.reflect.Method.invoke(Method.java:497)
	at org.testng.internal.MethodInvocationHelper.invokeMethod(MethodInvocationHelper.java:84)
	at org.testng.internal.Invoker.invokeMethod(Invoker.java:714)
	at org.testng.internal.Invoker.invokeTestMethod(Invoker.java:901)
	at org.testng.internal.TestMethodWithDataProviderMethodWorker.call(TestMethodWithDataProviderMethodWorker.java:73)
	at org.testng.internal.TestMethodWithDataProviderMethodWorker.call(TestMethodWithDataProviderMethodWorker.java:14)
	at java.util.concurrent.FutureTask.run(FutureTask.java:266)
	at java.util.concurrent.Executors$RunnableAdapter.call(Executors.java:511)
	at java.util.concurrent.FutureTask.run(FutureTask.java:266)
	at java.util.concurrent.ThreadPoolExecutor.runWorker(ThreadPoolExecutor.java:1142)
	at java.util.concurrent.ThreadPoolExecutor$Worker.run(ThreadPoolExecutor.java:617)
	at java.lang.Thread.run(Thread.java:745)
Caused by: org.openqa.selenium.WebDriverException: org.apache.http.conn.HttpHostConnectException: Connect to 127.0.0.1:4723 [/127.0.0.1] failed: Connection refused
Build info: version: '2.48.2', revision: '41bccdd', time: '2015-10-09 19:59:12'
System info: host: 'TVMATP310440M', ip: '10.155.190.178', os.name: 'Mac OS X', os.arch: 'x86_64', os.version: '10.12', java.version: '1.8.0_40'
Driver info: driver.version: AppiumDriver
	at io.appium.java_client.remote.AppiumCommandExecutor.execute(AppiumCommandExecutor.java:84)
	at org.openqa.selenium.remote.RemoteWebDriver.execute(RemoteWebDriver.java:620)
	... 22 more
Caused by: org.apache.http.conn.HttpHostConnectException: Connect to 127.0.0.1:4723 [/127.0.0.1] failed: Connection refused
	at org.apache.http.impl.conn.DefaultHttpClientConnectionOperator.connect(DefaultHttpClientConnectionOperator.java:151)
	at org.apache.http.impl.conn.PoolingHttpClientConnectionManager.connect(PoolingHttpClientConnectionManager.java:353)
	at org.apache.http.impl.execchain.MainClientExec.establishRoute(MainClientExec.java:380)
	at org.apache.http.impl.execchain.MainClientExec.execute(MainClientExec.java:236)
	at org.apache.http.impl.execchain.ProtocolExec.execute(ProtocolExec.java:184)
	at org.apache.http.impl.execchain.RetryExec.execute(RetryExec.java:88)
	at org.apache.http.impl.execchain.RedirectExec.execute(RedirectExec.java:110)
	at org.apache.http.impl.client.InternalHttpClient.doExecute(InternalHttpClient.java:184)
	at org.apache.http.impl.client.CloseableHttpClient.execute(CloseableHttpClient.java:71)
	at org.apache.http.impl.client.CloseableHttpClient.execute(CloseableHttpClient.java:55)
	at org.openqa.selenium.remote.internal.ApacheHttpClient.fallBackExecute(ApacheHttpClient.java:143)
	at org.openqa.selenium.remote.internal.ApacheHttpClient.execute(ApacheHttpClient.java:89)
	at org.openqa.selenium.remote.HttpCommandExecutor.execute(HttpCommandExecutor.java:142)
	at io.appium.java_client.remote.AppiumCommandExecutor.execute(AppiumCommandExecutor.java:69)
	... 23 more
Caused by: java.net.ConnectException: Connection refused
	at java.net.PlainSocketImpl.socketConnect(Native Method)
	at java.net.AbstractPlainSocketImpl.doConnect(AbstractPlainSocketImpl.java:345)
	at java.net.AbstractPlainSocketImpl.connectToAddress(AbstractPlainSocketImpl.java:206)
	at java.net.AbstractPlainSocketImpl.connect(AbstractPlainSocketImpl.java:188)
	at java.net.SocksSocketImpl.connect(SocksSocketImpl.java:392)
	at java.net.Socket.connect(Socket.java:589)
	at org.apache.http.conn.socket.PlainConnectionSocketFactory.connectSocket(PlainConnectionSocketFactory.java:74)
	at org.apache.http.impl.conn.DefaultHttpClientConnectionOperator.connect(DefaultHttpClientConnectionOperator.java:134)
	... 36 more
]]>
    </failure>
  </testcase> <!-- INV_ML_016_TI_059_CustomLoc_DeleteAllLoc_CustomCat_SetupCustomLoc_VerifyTrackInventory -->
</testsuite> <!-- com.uom.tests.ManageLocation -->
